<?xml version="1.0" ?>
  <sdf version="1.6">
  <!-- Important: This file is generated. DO NOT EDIT! -->
  <model name="rxi_dock">
    
        <!--
      This is how this dock should look like:

             X  X                X  X                X  X             XXXXXXXXXX             XXXX                XXXX             XXXXXXXXXX             X  X                X  X                X  X       
    -->




    <!-- Row 0 -->
    <include>
      <name>dock_block_0_3</name>
      <pose>0 6 0.25 0 0 0</pose>
        <uri>model://dock_block_4x4_dynamic</uri>
    </include>
    <include>
      <name>dock_block_0_6</name>
      <pose>0 12 0.25 0 0 0</pose>
        <uri>model://dock_block_4x4_dynamic</uri>
    </include>

    <!-- Row 1 -->
    <include>
      <name>dock_block_1_3</name>
      <pose>2 6 0.25 0 0 0</pose>
        <uri>model://dock_block_4x4_dynamic</uri>
    </include>
    <include>
      <name>dock_block_1_6</name>
      <pose>2 12 0.25 0 0 0</pose>
        <uri>model://dock_block_4x4_dynamic</uri>
    </include>

    <!-- Row 2 -->
    <include>
      <name>dock_block_2_3</name>
      <pose>4 6 0.25 0 0 0</pose>
        <uri>model://dock_block_4x4_dynamic</uri>
    </include>
    <include>
      <name>dock_block_2_6</name>
      <pose>4 12 0.25 0 0 0</pose>
        <uri>model://dock_block_4x4_dynamic</uri>
    </include>

    <!-- Row 3 -->
    <include>
      <name>dock_block_3_0</name>
      <pose>6 0 0.25 0 0 0</pose>
        <uri>model://dock_block_4x4_dynamic</uri>
    </include>
    <include>
      <name>dock_block_3_1</name>
      <pose>6 2 0.25 0 0 0</pose>
        <uri>model://dock_block_4x4_dynamic</uri>
    </include>
    <include>
      <name>dock_block_3_2</name>
      <pose>6 4 0.25 0 0 0</pose>
        <uri>model://dock_block_4x4_dynamic</uri>
    </include>
    <include>
      <name>dock_block_3_3</name>
      <pose>6 6 0.25 0 0 0</pose>
        <uri>model://dock_block_4x4_dynamic</uri>
    </include>
    <include>
      <name>dock_block_3_4</name>
      <pose>6 8 0.25 0 0 0</pose>
        <uri>model://dock_block_4x4_dynamic</uri>
    </include>
    <include>
      <name>dock_block_3_5</name>
      <pose>6 10 0.25 0 0 0</pose>
        <uri>model://dock_block_4x4_dynamic</uri>
    </include>
    <include>
      <name>dock_block_3_6</name>
      <pose>6 12 0.25 0 0 0</pose>
        <uri>model://dock_block_4x4_dynamic</uri>
    </include>
    <include>
      <name>dock_block_3_7</name>
      <pose>6 14 0.25 0 0 0</pose>
        <uri>model://dock_block_4x4_dynamic</uri>
    </include>
    <include>
      <name>dock_block_3_8</name>
      <pose>6 16 0.25 0 0 0</pose>
        <uri>model://dock_block_4x4_dynamic</uri>
    </include>
    <include>
      <name>dock_block_3_9</name>
      <pose>6 18 0.25 0 0 0</pose>
        <uri>model://dock_block_4x4_dynamic</uri>
    </include>

    <!-- Row 4 -->
    <include>
      <name>dock_block_4_3</name>
      <pose>8 6 0.25 0 0 0</pose>
        <uri>model://dock_block_4x4_dynamic</uri>
    </include>
    <include>
      <name>dock_block_4_4</name>
      <pose>8 8 0.25 0 0 0</pose>
        <uri>model://dock_block_4x4_dynamic</uri>
    </include>
    <include>
      <name>dock_block_4_5</name>
      <pose>8 10 0.25 0 0 0</pose>
        <uri>model://dock_block_4x4_dynamic</uri>
    </include>
    <include>
      <name>dock_block_4_6</name>
      <pose>8 12 0.25 0 0 0</pose>
        <uri>model://dock_block_4x4_dynamic</uri>
    </include>

    <!-- Row 5 -->
    <include>
      <name>dock_block_5_3</name>
      <pose>10 6 0.25 0 0 0</pose>
        <uri>model://dock_block_4x4_dynamic</uri>
    </include>
    <include>
      <name>dock_block_5_4</name>
      <pose>10 8 0.25 0 0 0</pose>
        <uri>model://dock_block_4x4_dynamic</uri>
    </include>
    <include>
      <name>dock_block_5_5</name>
      <pose>10 10 0.25 0 0 0</pose>
        <uri>model://dock_block_4x4_dynamic</uri>
    </include>
    <include>
      <name>dock_block_5_6</name>
      <pose>10 12 0.25 0 0 0</pose>
        <uri>model://dock_block_4x4_dynamic</uri>
    </include>

    <!-- Row 6 -->
    <include>
      <name>dock_block_6_0</name>
      <pose>12 0 0.25 0 0 0</pose>
        <uri>model://dock_block_4x4_dynamic</uri>
    </include>
    <include>
      <name>dock_block_6_1</name>
      <pose>12 2 0.25 0 0 0</pose>
        <uri>model://dock_block_4x4_dynamic</uri>
    </include>
    <include>
      <name>dock_block_6_2</name>
      <pose>12 4 0.25 0 0 0</pose>
        <uri>model://dock_block_4x4_dynamic</uri>
    </include>
    <include>
      <name>dock_block_6_3</name>
      <pose>12 6 0.25 0 0 0</pose>
        <uri>model://dock_block_4x4_dynamic</uri>
    </include>
    <include>
      <name>dock_block_6_4</name>
      <pose>12 8 0.25 0 0 0</pose>
        <uri>model://dock_block_4x4_dynamic</uri>
    </include>
    <include>
      <name>dock_block_6_5</name>
      <pose>12 10 0.25 0 0 0</pose>
        <uri>model://dock_block_4x4_dynamic</uri>
    </include>
    <include>
      <name>dock_block_6_6</name>
      <pose>12 12 0.25 0 0 0</pose>
        <uri>model://dock_block_4x4_dynamic</uri>
    </include>
    <include>
      <name>dock_block_6_7</name>
      <pose>12 14 0.25 0 0 0</pose>
        <uri>model://dock_block_4x4_dynamic</uri>
    </include>
    <include>
      <name>dock_block_6_8</name>
      <pose>12 16 0.25 0 0 0</pose>
        <uri>model://dock_block_4x4_dynamic</uri>
    </include>
    <include>
      <name>dock_block_6_9</name>
      <pose>12 18 0.25 0 0 0</pose>
        <uri>model://dock_block_4x4_dynamic</uri>
    </include>

    <!-- Row 7 -->
    <include>
      <name>dock_block_7_3</name>
      <pose>14 6 0.25 0 0 0</pose>
        <uri>model://dock_block_4x4_dynamic</uri>
    </include>
    <include>
      <name>dock_block_7_6</name>
      <pose>14 12 0.25 0 0 0</pose>
        <uri>model://dock_block_4x4_dynamic</uri>
    </include>

    <!-- Row 8 -->
    <include>
      <name>dock_block_8_3</name>
      <pose>16 6 0.25 0 0 0</pose>
        <uri>model://dock_block_4x4_dynamic</uri>
    </include>
    <include>
      <name>dock_block_8_6</name>
      <pose>16 12 0.25 0 0 0</pose>
        <uri>model://dock_block_4x4_dynamic</uri>
    </include>

    <!-- Row 9 -->
    <include>
      <name>dock_block_9_3</name>
      <pose>18 6 0.25 0 0 0</pose>
        <uri>model://dock_block_4x4_dynamic</uri>
    </include>
    <include>
      <name>dock_block_9_6</name>
      <pose>18 12 0.25 0 0 0</pose>
        <uri>model://dock_block_4x4_dynamic</uri>
    </include>




    <!-- Add joints across rows -->

    <!-- Row 0 -->

    <!-- Row 1 -->

    <!-- Row 2 -->

    <!-- Row 3 -->
    <joint name="3_0_to_3_1" type="revolute">
      <pose> 0  1.0 0 0 0 0</pose>
      <parent>dock_block_3_1::link</parent>
      <child>dock_block_3_0::link</child>
      <axis>
        <limit>
          <lower>-0.1</lower>
          <upper>0.1</upper>
        </limit>
        <xyz>1 0 0</xyz>
      </axis>
    </joint>
    <joint name="3_1_to_3_2" type="revolute">
      <pose> 0  1.0 0 0 0 0</pose>
      <parent>dock_block_3_2::link</parent>
      <child>dock_block_3_1::link</child>
      <axis>
        <limit>
          <lower>-0.1</lower>
          <upper>0.1</upper>
        </limit>
        <xyz>1 0 0</xyz>
      </axis>
    </joint>
    <joint name="3_2_to_3_3" type="revolute">
      <pose> 0  1.0 0 0 0 0</pose>
      <parent>dock_block_3_3::link</parent>
      <child>dock_block_3_2::link</child>
      <axis>
        <limit>
          <lower>-0.1</lower>
          <upper>0.1</upper>
        </limit>
        <xyz>1 0 0</xyz>
      </axis>
    </joint>
    <joint name="3_3_to_3_4" type="revolute">
      <pose> 0  1.0 0 0 0 0</pose>
      <parent>dock_block_3_4::link</parent>
      <child>dock_block_3_3::link</child>
      <axis>
        <limit>
          <lower>-0.1</lower>
          <upper>0.1</upper>
        </limit>
        <xyz>1 0 0</xyz>
      </axis>
    </joint>
    <joint name="3_4_to_3_5" type="revolute">
      <pose> 0  1.0 0 0 0 0</pose>
      <parent>dock_block_3_5::link</parent>
      <child>dock_block_3_4::link</child>
      <axis>
        <limit>
          <lower>-0.1</lower>
          <upper>0.1</upper>
        </limit>
        <xyz>1 0 0</xyz>
      </axis>
    </joint>
    <joint name="3_5_to_3_6" type="revolute">
      <pose> 0  1.0 0 0 0 0</pose>
      <parent>dock_block_3_6::link</parent>
      <child>dock_block_3_5::link</child>
      <axis>
        <limit>
          <lower>-0.1</lower>
          <upper>0.1</upper>
        </limit>
        <xyz>1 0 0</xyz>
      </axis>
    </joint>
    <joint name="3_6_to_3_7" type="revolute">
      <pose> 0  1.0 0 0 0 0</pose>
      <parent>dock_block_3_7::link</parent>
      <child>dock_block_3_6::link</child>
      <axis>
        <limit>
          <lower>-0.1</lower>
          <upper>0.1</upper>
        </limit>
        <xyz>1 0 0</xyz>
      </axis>
    </joint>
    <joint name="3_7_to_3_8" type="revolute">
      <pose> 0  1.0 0 0 0 0</pose>
      <parent>dock_block_3_8::link</parent>
      <child>dock_block_3_7::link</child>
      <axis>
        <limit>
          <lower>-0.1</lower>
          <upper>0.1</upper>
        </limit>
        <xyz>1 0 0</xyz>
      </axis>
    </joint>
    <joint name="3_8_to_3_9" type="revolute">
      <pose> 0  1.0 0 0 0 0</pose>
      <parent>dock_block_3_9::link</parent>
      <child>dock_block_3_8::link</child>
      <axis>
        <limit>
          <lower>-0.1</lower>
          <upper>0.1</upper>
        </limit>
        <xyz>1 0 0</xyz>
      </axis>
    </joint>

    <!-- Row 4 -->
    <joint name="4_3_to_4_4" type="revolute">
      <pose> 0  1.0 0 0 0 0</pose>
      <parent>dock_block_4_4::link</parent>
      <child>dock_block_4_3::link</child>
      <axis>
        <limit>
          <lower>-0.1</lower>
          <upper>0.1</upper>
        </limit>
        <xyz>1 0 0</xyz>
      </axis>
    </joint>
    <joint name="4_4_to_4_5" type="revolute">
      <pose> 0  1.0 0 0 0 0</pose>
      <parent>dock_block_4_5::link</parent>
      <child>dock_block_4_4::link</child>
      <axis>
        <limit>
          <lower>-0.1</lower>
          <upper>0.1</upper>
        </limit>
        <xyz>1 0 0</xyz>
      </axis>
    </joint>
    <joint name="4_5_to_4_6" type="revolute">
      <pose> 0  1.0 0 0 0 0</pose>
      <parent>dock_block_4_6::link</parent>
      <child>dock_block_4_5::link</child>
      <axis>
        <limit>
          <lower>-0.1</lower>
          <upper>0.1</upper>
        </limit>
        <xyz>1 0 0</xyz>
      </axis>
    </joint>

    <!-- Row 5 -->
    <joint name="5_3_to_5_4" type="revolute">
      <pose> 0  1.0 0 0 0 0</pose>
      <parent>dock_block_5_4::link</parent>
      <child>dock_block_5_3::link</child>
      <axis>
        <limit>
          <lower>-0.1</lower>
          <upper>0.1</upper>
        </limit>
        <xyz>1 0 0</xyz>
      </axis>
    </joint>
    <joint name="5_4_to_5_5" type="revolute">
      <pose> 0  1.0 0 0 0 0</pose>
      <parent>dock_block_5_5::link</parent>
      <child>dock_block_5_4::link</child>
      <axis>
        <limit>
          <lower>-0.1</lower>
          <upper>0.1</upper>
        </limit>
        <xyz>1 0 0</xyz>
      </axis>
    </joint>
    <joint name="5_5_to_5_6" type="revolute">
      <pose> 0  1.0 0 0 0 0</pose>
      <parent>dock_block_5_6::link</parent>
      <child>dock_block_5_5::link</child>
      <axis>
        <limit>
          <lower>-0.1</lower>
          <upper>0.1</upper>
        </limit>
        <xyz>1 0 0</xyz>
      </axis>
    </joint>

    <!-- Row 6 -->
    <joint name="6_0_to_6_1" type="revolute">
      <pose> 0  1.0 0 0 0 0</pose>
      <parent>dock_block_6_1::link</parent>
      <child>dock_block_6_0::link</child>
      <axis>
        <limit>
          <lower>-0.1</lower>
          <upper>0.1</upper>
        </limit>
        <xyz>1 0 0</xyz>
      </axis>
    </joint>
    <joint name="6_1_to_6_2" type="revolute">
      <pose> 0  1.0 0 0 0 0</pose>
      <parent>dock_block_6_2::link</parent>
      <child>dock_block_6_1::link</child>
      <axis>
        <limit>
          <lower>-0.1</lower>
          <upper>0.1</upper>
        </limit>
        <xyz>1 0 0</xyz>
      </axis>
    </joint>
    <joint name="6_2_to_6_3" type="revolute">
      <pose> 0  1.0 0 0 0 0</pose>
      <parent>dock_block_6_3::link</parent>
      <child>dock_block_6_2::link</child>
      <axis>
        <limit>
          <lower>-0.1</lower>
          <upper>0.1</upper>
        </limit>
        <xyz>1 0 0</xyz>
      </axis>
    </joint>
    <joint name="6_3_to_6_4" type="revolute">
      <pose> 0  1.0 0 0 0 0</pose>
      <parent>dock_block_6_4::link</parent>
      <child>dock_block_6_3::link</child>
      <axis>
        <limit>
          <lower>-0.1</lower>
          <upper>0.1</upper>
        </limit>
        <xyz>1 0 0</xyz>
      </axis>
    </joint>
    <joint name="6_4_to_6_5" type="revolute">
      <pose> 0  1.0 0 0 0 0</pose>
      <parent>dock_block_6_5::link</parent>
      <child>dock_block_6_4::link</child>
      <axis>
        <limit>
          <lower>-0.1</lower>
          <upper>0.1</upper>
        </limit>
        <xyz>1 0 0</xyz>
      </axis>
    </joint>
    <joint name="6_5_to_6_6" type="revolute">
      <pose> 0  1.0 0 0 0 0</pose>
      <parent>dock_block_6_6::link</parent>
      <child>dock_block_6_5::link</child>
      <axis>
        <limit>
          <lower>-0.1</lower>
          <upper>0.1</upper>
        </limit>
        <xyz>1 0 0</xyz>
      </axis>
    </joint>
    <joint name="6_6_to_6_7" type="revolute">
      <pose> 0  1.0 0 0 0 0</pose>
      <parent>dock_block_6_7::link</parent>
      <child>dock_block_6_6::link</child>
      <axis>
        <limit>
          <lower>-0.1</lower>
          <upper>0.1</upper>
        </limit>
        <xyz>1 0 0</xyz>
      </axis>
    </joint>
    <joint name="6_7_to_6_8" type="revolute">
      <pose> 0  1.0 0 0 0 0</pose>
      <parent>dock_block_6_8::link</parent>
      <child>dock_block_6_7::link</child>
      <axis>
        <limit>
          <lower>-0.1</lower>
          <upper>0.1</upper>
        </limit>
        <xyz>1 0 0</xyz>
      </axis>
    </joint>
    <joint name="6_8_to_6_9" type="revolute">
      <pose> 0  1.0 0 0 0 0</pose>
      <parent>dock_block_6_9::link</parent>
      <child>dock_block_6_8::link</child>
      <axis>
        <limit>
          <lower>-0.1</lower>
          <upper>0.1</upper>
        </limit>
        <xyz>1 0 0</xyz>
      </axis>
    </joint>

    <!-- Row 7 -->

    <!-- Row 8 -->

    <!-- Row 9 -->



    <!-- Add joints across columns -->

    <!-- Column 0 -->

    <!-- Column 1 -->

    <!-- Column 2 -->

    <!-- Column 3 -->
    <joint name="1_3_to_0_3" type="revolute">
      <pose> 1.0 0 0 0 0 0</pose>
      <parent>dock_block_1_3::link</parent>
      <child>dock_block_0_3::link</child>
      <axis>
        <limit>
          <lower>-0.1</lower>
          <upper>0.1</upper>
        </limit>
        <xyz>0 1 0</xyz>
      </axis>
    </joint>
    <joint name="2_3_to_1_3" type="revolute">
      <pose> 1.0 0 0 0 0 0</pose>
      <parent>dock_block_2_3::link</parent>
      <child>dock_block_1_3::link</child>
      <axis>
        <limit>
          <lower>-0.1</lower>
          <upper>0.1</upper>
        </limit>
        <xyz>0 1 0</xyz>
      </axis>
    </joint>
    <joint name="3_3_to_2_3" type="revolute">
      <pose> 1.0 0 0 0 0 0</pose>
      <parent>dock_block_3_3::link</parent>
      <child>dock_block_2_3::link</child>
      <axis>
        <limit>
          <lower>-0.1</lower>
          <upper>0.1</upper>
        </limit>
        <xyz>0 1 0</xyz>
      </axis>
    </joint>
    <joint name="4_3_to_3_3" type="revolute">
      <pose> 1.0 0 0 0 0 0</pose>
      <parent>dock_block_4_3::link</parent>
      <child>dock_block_3_3::link</child>
      <axis>
        <limit>
          <lower>-0.1</lower>
          <upper>0.1</upper>
        </limit>
        <xyz>0 1 0</xyz>
      </axis>
    </joint>
    <joint name="5_3_to_4_3" type="revolute">
      <pose> 1.0 0 0 0 0 0</pose>
      <parent>dock_block_5_3::link</parent>
      <child>dock_block_4_3::link</child>
      <axis>
        <limit>
          <lower>-0.1</lower>
          <upper>0.1</upper>
        </limit>
        <xyz>0 1 0</xyz>
      </axis>
    </joint>
    <joint name="6_3_to_5_3" type="revolute">
      <pose> 1.0 0 0 0 0 0</pose>
      <parent>dock_block_6_3::link</parent>
      <child>dock_block_5_3::link</child>
      <axis>
        <limit>
          <lower>-0.1</lower>
          <upper>0.1</upper>
        </limit>
        <xyz>0 1 0</xyz>
      </axis>
    </joint>
    <joint name="7_3_to_6_3" type="revolute">
      <pose> 1.0 0 0 0 0 0</pose>
      <parent>dock_block_7_3::link</parent>
      <child>dock_block_6_3::link</child>
      <axis>
        <limit>
          <lower>-0.1</lower>
          <upper>0.1</upper>
        </limit>
        <xyz>0 1 0</xyz>
      </axis>
    </joint>
    <joint name="8_3_to_7_3" type="revolute">
      <pose> 1.0 0 0 0 0 0</pose>
      <parent>dock_block_8_3::link</parent>
      <child>dock_block_7_3::link</child>
      <axis>
        <limit>
          <lower>-0.1</lower>
          <upper>0.1</upper>
        </limit>
        <xyz>0 1 0</xyz>
      </axis>
    </joint>
    <joint name="9_3_to_8_3" type="revolute">
      <pose> 1.0 0 0 0 0 0</pose>
      <parent>dock_block_9_3::link</parent>
      <child>dock_block_8_3::link</child>
      <axis>
        <limit>
          <lower>-0.1</lower>
          <upper>0.1</upper>
        </limit>
        <xyz>0 1 0</xyz>
      </axis>
    </joint>

    <!-- Column 4 -->
    <joint name="4_4_to_3_4" type="revolute">
      <pose> 1.0 0 0 0 0 0</pose>
      <parent>dock_block_4_4::link</parent>
      <child>dock_block_3_4::link</child>
      <axis>
        <limit>
          <lower>-0.1</lower>
          <upper>0.1</upper>
        </limit>
        <xyz>0 1 0</xyz>
      </axis>
    </joint>
    <joint name="5_4_to_4_4" type="revolute">
      <pose> 1.0 0 0 0 0 0</pose>
      <parent>dock_block_5_4::link</parent>
      <child>dock_block_4_4::link</child>
      <axis>
        <limit>
          <lower>-0.1</lower>
          <upper>0.1</upper>
        </limit>
        <xyz>0 1 0</xyz>
      </axis>
    </joint>
    <joint name="6_4_to_5_4" type="revolute">
      <pose> 1.0 0 0 0 0 0</pose>
      <parent>dock_block_6_4::link</parent>
      <child>dock_block_5_4::link</child>
      <axis>
        <limit>
          <lower>-0.1</lower>
          <upper>0.1</upper>
        </limit>
        <xyz>0 1 0</xyz>
      </axis>
    </joint>

    <!-- Column 5 -->
    <joint name="4_5_to_3_5" type="revolute">
      <pose> 1.0 0 0 0 0 0</pose>
      <parent>dock_block_4_5::link</parent>
      <child>dock_block_3_5::link</child>
      <axis>
        <limit>
          <lower>-0.1</lower>
          <upper>0.1</upper>
        </limit>
        <xyz>0 1 0</xyz>
      </axis>
    </joint>
    <joint name="5_5_to_4_5" type="revolute">
      <pose> 1.0 0 0 0 0 0</pose>
      <parent>dock_block_5_5::link</parent>
      <child>dock_block_4_5::link</child>
      <axis>
        <limit>
          <lower>-0.1</lower>
          <upper>0.1</upper>
        </limit>
        <xyz>0 1 0</xyz>
      </axis>
    </joint>
    <joint name="6_5_to_5_5" type="revolute">
      <pose> 1.0 0 0 0 0 0</pose>
      <parent>dock_block_6_5::link</parent>
      <child>dock_block_5_5::link</child>
      <axis>
        <limit>
          <lower>-0.1</lower>
          <upper>0.1</upper>
        </limit>
        <xyz>0 1 0</xyz>
      </axis>
    </joint>

    <!-- Column 6 -->
    <joint name="1_6_to_0_6" type="revolute">
      <pose> 1.0 0 0 0 0 0</pose>
      <parent>dock_block_1_6::link</parent>
      <child>dock_block_0_6::link</child>
      <axis>
        <limit>
          <lower>-0.1</lower>
          <upper>0.1</upper>
        </limit>
        <xyz>0 1 0</xyz>
      </axis>
    </joint>
    <joint name="2_6_to_1_6" type="revolute">
      <pose> 1.0 0 0 0 0 0</pose>
      <parent>dock_block_2_6::link</parent>
      <child>dock_block_1_6::link</child>
      <axis>
        <limit>
          <lower>-0.1</lower>
          <upper>0.1</upper>
        </limit>
        <xyz>0 1 0</xyz>
      </axis>
    </joint>
    <joint name="3_6_to_2_6" type="revolute">
      <pose> 1.0 0 0 0 0 0</pose>
      <parent>dock_block_3_6::link</parent>
      <child>dock_block_2_6::link</child>
      <axis>
        <limit>
          <lower>-0.1</lower>
          <upper>0.1</upper>
        </limit>
        <xyz>0 1 0</xyz>
      </axis>
    </joint>
    <joint name="4_6_to_3_6" type="revolute">
      <pose> 1.0 0 0 0 0 0</pose>
      <parent>dock_block_4_6::link</parent>
      <child>dock_block_3_6::link</child>
      <axis>
        <limit>
          <lower>-0.1</lower>
          <upper>0.1</upper>
        </limit>
        <xyz>0 1 0</xyz>
      </axis>
    </joint>
    <joint name="5_6_to_4_6" type="revolute">
      <pose> 1.0 0 0 0 0 0</pose>
      <parent>dock_block_5_6::link</parent>
      <child>dock_block_4_6::link</child>
      <axis>
        <limit>
          <lower>-0.1</lower>
          <upper>0.1</upper>
        </limit>
        <xyz>0 1 0</xyz>
      </axis>
    </joint>
    <joint name="6_6_to_5_6" type="revolute">
      <pose> 1.0 0 0 0 0 0</pose>
      <parent>dock_block_6_6::link</parent>
      <child>dock_block_5_6::link</child>
      <axis>
        <limit>
          <lower>-0.1</lower>
          <upper>0.1</upper>
        </limit>
        <xyz>0 1 0</xyz>
      </axis>
    </joint>
    <joint name="7_6_to_6_6" type="revolute">
      <pose> 1.0 0 0 0 0 0</pose>
      <parent>dock_block_7_6::link</parent>
      <child>dock_block_6_6::link</child>
      <axis>
        <limit>
          <lower>-0.1</lower>
          <upper>0.1</upper>
        </limit>
        <xyz>0 1 0</xyz>
      </axis>
    </joint>
    <joint name="8_6_to_7_6" type="revolute">
      <pose> 1.0 0 0 0 0 0</pose>
      <parent>dock_block_8_6::link</parent>
      <child>dock_block_7_6::link</child>
      <axis>
        <limit>
          <lower>-0.1</lower>
          <upper>0.1</upper>
        </limit>
        <xyz>0 1 0</xyz>
      </axis>
    </joint>
    <joint name="9_6_to_8_6" type="revolute">
      <pose> 1.0 0 0 0 0 0</pose>
      <parent>dock_block_9_6::link</parent>
      <child>dock_block_8_6::link</child>
      <axis>
        <limit>
          <lower>-0.1</lower>
          <upper>0.1</upper>
        </limit>
        <xyz>0 1 0</xyz>
      </axis>
    </joint>

    <!-- Column 7 -->

    <!-- Column 8 -->

    <!-- Column 9 -->



  </model>
</sdf>